Workbook

Sheet Dashboard
A1: DASHBOARD FOR ONLINE ASSESSMENTS
C4: Section A | CO4: Section B | CU4: Section C | FK4: Section D | HG4: Section E | IM4: Section F
CU5: 1 | CV5: 2 | CW5: 3 | CX5: 4 | CY5: 5 | CZ5: 6 | DA5: 7 | DB5: 8 | DC5: 9 | DD5: 10 | DE5: 11 | DF5: 12 | DG5: 13 | DH5: 14 | DI5: 15 | DJ5: 16 | DK5: 17 | DL5: 18 | DM5: 19 | DN5: 20 | DO5: 21 | DP5: 22 | DQ5: 23 | DR5: 24 | DS5: 25 | DT5: 26 | DU5: 27 | DV5: 28 | DW5: 29 | DX5: 30 | DY5: 31 | DZ5: 32 | EA5: 33 | EB5: 34 | EC5: 35 | ED5: 36 | EE5: 37 | EF5: 38 | EG5: 39 | EH5: 40 | EI5: 41 | EJ5: 42 | EK5: 43 | EL5: 44 | EM5: 45 | EN5: 46 | EO5: 47 | EP5: 48 | EQ5: 49 | ER5: 50 | ES5: 51 | ET5: 52 | EU5: 53 | EV5: 54 | EW5: 55 | EX5: 56 | EY5: 57 | EZ5: 58 | FA5: 59 | FB5: 60 | FC5: 61 | FD5: 62 | FE5: 63 | FF5: 64 | FG5: 65 | FH5: 66 | FI5: 67 | FJ5: 68 | FK5: 1 | FL5: 2 | FM5: 3 | FN5: 4 | FO5: 5 | FP5: 6 | FQ5: 7 | FR5: 8 | FS5: 9 | FT5: 10 | FU5: 11 | FV5: 12 | FW5: 13 | FX5: 14 | FY5: 15 | FZ5: 16 | GA5: 17 | GB5: 18 | GC5: 19 | GD5: 20 | GE5: 21 | GF5: 22 | GG5: 23 | GH5: 24 | GI5: 25 | GJ5: 26 | GK5: 27 | GL5: 28 | GM5: 29 | GN5: 30 | GO5: 31 | GP5: 32 | GQ5: 33 | GR5: 34 | GS5: 35 | GT5: 36 | GU5: 37 | GV5: 38 | GW5: 39 | GX5: 40 | GY5: 41 | GZ5: 42 | HA5: 43 | HB5: 44 | HC5: 45 | HD5: 46 | HE5: 47 | HF5: 48 | IM5: 1a | IN5: 1b | IO5: 1c | IP5: 1d | IQ5: 1e | IR5: 2a | IS5: 2b | IT5: 2c | IU5: 2d | IV5: 2e | IW5: 3a | IX5: 3b | IY5: 3c | IZ5: 3d | JA5: 4a | JB5: 4b | JC5: 4c | JD5: 4d | JE5: 4e | JF5: Section E | JG5: Section E | JH5: Section E | JI5: Section E | JJ5: Section E | JK5: Section E | JL5: Section E | JM5: Section E | JN5: Section E | JO5: Section E | JP5: Section E | JQ5: Section E | JR5: Section E | JS5: Section E | JT5: Section E | JU5: Section E
C6: R | R6: A | AG6: E | AV6: I | BK6: S | BZ6: C | CO6: R | CP6: A | CQ6: I | CR6: S | CS6: E | CT6: C | CU6: E or I | DJ6: S or N | EA6: T or F | ET6: J or P | HG6: A | HI6: C | HK6: V | HM6: B | HO6: E | HQ6: F | HS6: G | HU6: H | HW6: T | HY6: S | IA6: I | IC6: P | IE6: M | IG6: N | II6: Y | IK6: D | JF6: A | JG6: C | JH6: V | JI6: B | JJ6: E | JK6: F | JL6: G | JM6: H | JN6: T | JO6: S | JP6: I | JQ6: P | JR6: M | JS6: N | JT6: Y | JU6: D
A7: Student Name | C7: Q1 | D7: Q2 | E7: Q3 | F7: Q4 | G7: Q5 | H7: Q6 | I7: Q7 | J7: Q8 | K7: Q9 | L7: Q10 | M7: Q11 | N7: Q12 | O7: Q13 | P7: Q14 | Q7: Q15 | R7: Q16 | S7: Q17 | T7: Q18 | U7: Q19 | V7: Q20 | W7: Q21 | X7: Q22 | Y7: Q23 | Z7: Q24 | AA7: Q25 | AB7: Q26 | AC7: Q27 | AD7: Q28 | AE7: Q29 | AF7: Q30 | AG7: Q31 | AH7: Q32 | AI7: Q33 | AJ7: Q34 | AK7: Q35 | AL7: Q36 | AM7: Q37 | AN7: Q38 | AO7: Q39 | AP7: Q40 | AQ7: Q41 | AR7: Q42 | AS7: Q43 | AT7: Q44 | AU7: Q45 | AV7: Q46 | AW7: Q47 | AX7: Q48 | AY7: Q49 | AZ7: Q50 | BA7: Q51 | BB7: Q52 | BC7: Q53 | BD7: Q54 | BE7: Q55 | BF7: Q56 | BG7: Q57 | BH7: Q58 | BI7: Q59 | BJ7: Q60 | BK7: Q61 | BL7: Q62 | BM7: Q63 | BN7: Q64 | BO7: Q65 | BP7: Q66 | BQ7: Q67 | BR7: Q68 | BS7: Q69 | BT7: Q70 | BU7: Q71 | BV7: Q72 | BW7: Q73 | BX7: Q74 | BY7: Q75 | BZ7: Q76 | CA7: Q77 | CB7: Q78 | CC7: Q79 | CD7: Q80 | CE7: Q81 | CF7: Q82 | CG7: Q83 | CH7: Q84 | CI7: Q85 | CJ7: Q86 | CK7: Q87 | CL7: Q88 | CM7: Q89 | CN7: Q90 | CO7: Q91 | CP7: Q92 | CQ7: Q93 | CR7: Q94 | CS7: Q95 | CT7: Q96 | CU7: Q97 | CV7: Q98 | CW7: Q99 | CX7: Q100 | CY7: Q101 | CZ7: Q102 | DA7: Q103 | DB7: Q104 | DC7: Q105 | DD7: Q106 | DE7: Q107 | DF7: Q108 | DG7: Q109 | DH7: Q110 | DI7: Q111 | DJ7: Q112 | DK7: Q113 | DL7: Q114 | DM7: Q115 | DN7: Q116 | DO7: Q117 | DP7: Q118 | DQ7: Q119 | DR7: Q120 | DS7: Q121 | DT7: Q122 | DU7: Q123 | DV7: Q124 | DW7: Q125 | DX7: Q126 | DY7: Q127 | DZ7: Q128 | EA7: Q129 | EB7: Q130 | EC7: Q131 | ED7: Q132 | EE7: Q133 | EF7: Q134 | EG7: Q135 | EH7: Q136 | EI7: Q137 | EJ7: Q138 | EK7: Q139 | EL7: Q140 | EM7: Q141 | EN7: Q142 | EO7: Q143 | EP7: Q144 | EQ7: Q145 | ER7: Q146 | ES7: Q147 | ET7: Q148 | EU7: Q149 | EV7: Q150 | EW7: Q151 | EX7: Q152 | EY7: Q153 | EZ7: Q154 | FA7: Q155 | FB7: Q156 | FC7: Q157 | FD7: Q158 | FE7: Q159 | FF7: Q160 | FG7: Q161 | FH7: Q162 | FI7: Q163 | FJ7: Q164 | FK7: Q165 | FL7: Q166 | FM7: Q167 | FN7: Q168 | FO7: Q169 | FP7: Q170 | FQ7: Q171 | FR7: Q172 | FS7: Q173 | FT7: Q174 | FU7: Q175 | FV7: Q176 | FW7: Q177 | FX7: Q178 | FY7: Q179 | FZ7: Q180 | GA7: Q181 | GB7: Q182 | GC7: Q183 | GD7: Q184 | GE7: Q185 | GF7: Q186 | GG7: Q187 | GH7: Q188 | GI7: Q189 | GJ7: Q190 | GK7: Q191 | GL7: Q192 | GM7: Q193 | GN7: Q194 | GO7: Q195 | GP7: Q196 | GQ7: Q197 | GR7: Q198 | GS7: Q199 | GT7: Q200 | GU7: Q201 | GV7: Q202 | GW7: Q203 | GX7: Q204 | GY7: Q205 | GZ7: Q206 | HA7: Q207 | HB7: Q208 | HC7: Q209 | HD7: Q210 | HE7: Q211 | HF7: Q212 | HG7: Q213 | HH7: Q214 | HI7: Q215 | HJ7: Q216 | HK7: Q217 | HL7: Q218 | HM7: Q219 | HN7: Q220 | HO7: Q221 | HP7: Q222 | HQ7: Q223 | HR7: Q224 | HS7: Q225 | HT7: Q226 | HU7: Q227 | HV7: Q228 | HW7: Q229 | HX7: Q230 | HY7: Q231 | HZ7: Q232 | IA7: Q233 | IB7: Q234 | IC7: Q235 | ID7: Q236 | IE7: Q237 | IF7: Q238 | IG7: Q239 | IH7: Q240 | II7: Q241 | IJ7: Q242 | IK7: Q243 | IL7: Q244 | IM7: Q245 | IN7: Q246 | IO7: Q247 | IP7: Q248 | IQ7: Q249 | IR7: Q250 | IS7: Q251 | IT7: Q252 | IU7: Q253 | IV7: Q254 | IW7: Q255 | IX7: Q256 | IY7: Q257 | IZ7: Q258 | JA7: Q259 | JB7: Q260 | JC7: Q261 | JD7: Q262 | JE7: Q263 | JF7: Q264 | JG7: Q265 | JH7: Q266 | JI7: Q267 | JJ7: Q268 | JK7: Q269 | JL7: Q270 | JM7: Q271 | JN7: Q272 | JO7: Q273 | JP7: Q274 | JQ7: Q275 | JR7: Q276 | JS7: Q277 | JT7: Q278 | JU7: Q279
B8: Insert student answers here | C8: 0 | D8: 1 | E8: 0 | F8: 0 | G8: 1 | H8: 1 | I8: 0 | J8: 0 | K8: 0 | L8: 1 | M8: 0 | N8: 0 | O8: 1 | P8: 1 | Q8: 1 | R8: 0 | S8: 0 | T8: 1 | U8: 0 | V8: 0 | W8: 0 | X8: 0 | Y8: 0 | Z8: 1 | AA8: 0 | AB8: 0 | AC8: 0 | AD8: 0 | AE8: 0 | AF8: 0 | AG8: 0 | AH8: 0 | AI8: 0 | AJ8: 0 | AK8: 1 | AL8: 0 | AM8: 0 | AN8: 0 | AO8: 1 | AP8: 0 | AQ8: 0 | AR8: 1 | AS8: 1 | AT8: 0 | AU8: 0 | AV8: 1 | AW8: 0 | AX8: 0 | AY8: 1 | AZ8: 1 | BA8: 0 | BB8: 0 | BC8: 0 | BD8: 0 | BE8: 1 | BF8: 0 | BG8: 0 | BH8: 0 | BI8: 1 | BJ8: 1 | BK8: 1 | BL8: 0 | BM8: 1 | BN8: 1 | BO8: 0 | BP8: 1 | BQ8: 0 | BR8: 0 | BS8: 1 | BT8: 1 | BU8: 0 | BV8: 0 | BW8: 1 | BX8: 0 | BY8: 0 | BZ8: 0 | CA8: 1 | CB8: 1 | CC8: 1 | CD8: 1 | CE8: 1 | CF8: 1 | CG8: 1 | CH8: 1 | CI8: 0 | CJ8: 0 | CK8: 0 | CL8: 0 | CM8: 0 | CN8: 1 | CO8: 2 | CP8: 1 | CQ8: 0 | CR8: 1 | CS8: 2 | CT8: 1 | CU8: 1 | CV8: 0 | CW8: 0 | CX8: 1 | CY8: 1 | CZ8: 1 | DA8: 0 | DB8: 0 | DC8: 0 | DD8: 0 | DE8: 0 | DF8: 0 | DG8: 0 | DH8: 0 | DI8: 0 | DJ8: 0 | DK8: 1 | DL8: 1 | DM8: 0 | DN8: 1 | DO8: 1 | DP8: 1 | DQ8: 0 | DR8: 0 | DS8: 1 | DT8: 1 | DU8: 1 | DV8: 1 | DW8: 1 | DX8: 0 | DY8: 1 | DZ8: 1 | EA8: 0 | EB8: 0 | EC8: 0 | ED8: 0 | EE8: 1 | EF8: 1 | EG8: 0 | EH8: 1 | EI8: 1 | EJ8: 0 | EK8: 1 | EL8: 1 | EM8: 0 | EN8: 0 | EO8: 0 | EP8: 0 | EQ8: 0 | ER8: 0 | ES8: 0 | ET8: 1 | EU8: 1 | EV8: 0 | EW8: 1 | EX8: 1 | EY8: 1 | EZ8: 1 | FA8: 1 | FB8: 1 | FC8: 1 | FD8: 0 | FE8: 0 | FF8: 0 | FG8: 1 | FH8: 0 | FI8: 0 | FJ8: 0 | FK8: 0 | FL8: 1 | FM8: 1 | FN8: 1 | FO8: 0 | FP8: 1 | FQ8: 0 | FR8: 1 | FS8: 0 | FT8: 1 | FU8: 1 | FV8: 1 | FW8: 0 | FX8: 0 | FY8: 0 | FZ8: 1 | GA8: 1 | GB8: 1 | GC8: 0 | GD8: 1 | GE8: 1 | GF8: 1 | GG8: 0 | GH8: 0 | GI8: 0 | GJ8: 1 | GK8: 0 | GL8: 1 | GM8: 1 | GN8: 1 | GO8: 1 | GP8: 1 | GQ8: 0 | GR8: 1 | GS8: 1 | GT8: 0 | GU8: 0 | GV8: 0 | GW8: 0 | GX8: 1 | GY8: 1 | GZ8: 1 | HA8: 1 | HB8: 1 | HC8: 0 | HD8: 1 | HE8: 0 | HF8: 1 | HG8: 1 | HH8: 0 | HI8: 4 | HJ8: 2 | HK8: 1 | HL8: 1 | HM8: 3 | HN8: 2 | HO8: 2 | HP8: 2 | HQ8: 4 | HR8: 0 | HS8: 3 | HT8: 2 | HU8: 3 | HV8: 2 | HW8: 2 | HX8: 3 | HY8: 3 | HZ8: 1 | IA8: 0 | IB8: 2 | IC8: 2 | ID8: 1 | IE8: 4 | IF8: 3 | IG8: 2 | IH8: 1 | II8: 0 | IJ8: 1 | IK8: 2 | IL8: 2 | IM8: 0 | IN8: 1 | IO8: 1 | IP8: 0 | IQ8: 0 | IR8: 0 | IS8: 1 | IT8: 0 | IU8: 1 | IV8: 1 | IW8: 1 | IX8: 1 | IY8: 1 | IZ8: 0 | JA8: 0 | JB8: 1 | JC8: 1 | JD8: 1 | JE8: 1 | JF8: 0 | JG8: 0 | JH8: 1 | JI8: 1 | JJ8: 0 | JK8: 1 | JL8: 0 | JM8: 0 | JN8: 0 | JO8: 0 | JP8: 0 | JQ8: 0 | JR8: 0 | JS8: 1 | JT8: 0 | JU8: 1

Sheet SEC A & B 
A1: ANSWER SHEET - SECTION A (fill data in blue cells only) (Yes = 1 and No = 0)
B3: S.No | D3: Answers | E3: TOTAL
A4: R | B4: 1 | D4: =Dashboard!C8 -> 0
B5: 2 | D5: =Dashboard!D8 -> 1
B6: 3 | D6: =Dashboard!E8 -> 0
B7: 4 | D7: =Dashboard!F8 -> 0
B8: 5 | D8: =Dashboard!G8 -> 1
B9: 6 | D9: =Dashboard!H8 -> 1
B10: 7 | D10: =Dashboard!I8 -> 0
B11: 8 | D11: =Dashboard!J8 -> 0
B12: 9 | D12: =Dashboard!K8 -> 0
B13: 10 | D13: =Dashboard!L8 -> 1
B14: 11 | D14: =Dashboard!M8 -> 0
B15: 12 | D15: =Dashboard!N8 -> 0
B16: 13 | D16: =Dashboard!O8 -> 1
B17: 14 | D17: =Dashboard!P8 -> 1
B18: 15 | D18: =Dashboard!Q8 -> 1
D19: =D105+R117 -> 2 | E19: =SUM(D4:D19) -> 9 | F19: =E19 -> 9
A20: A | B20: 16 | D20: =Dashboard!R8 -> 0
B21: 17 | D21: =Dashboard!S8 -> 0
B22: 18 | D22: =Dashboard!T8 -> 1
B23: 19 | D23: =Dashboard!U8 -> 0
B24: 20 | D24: =Dashboard!V8 -> 0
B25: 21 | D25: =Dashboard!W8 -> 0
B26: 22 | D26: =Dashboard!X8 -> 0
B27: 23 | D27: =Dashboard!Y8 -> 0
B28: 24 | D28: =Dashboard!Z8 -> 1
B29: 25 | D29: =Dashboard!AA8 -> 0
B30: 26 | D30: =Dashboard!AB8 -> 0
B31: 27 | D31: =Dashboard!AC8 -> 0
B32: 28 | D32: =Dashboard!AD8 -> 0
B33: 29 | D33: =Dashboard!AE8 -> 0
B34: 30 | D34: =Dashboard!AF8 -> 0
D35: =D106+R118 -> 1 | E35: =SUM(D20:D35) -> 3 | F35: =E35 -> 3
A36: E | B36: 31 | D36: =Dashboard!AG8 -> 0
B37: 32 | D37: =Dashboard!AH8 -> 0
B38: 33 | D38: =Dashboard!AI8 -> 0
B39: 34 | D39: =Dashboard!AJ8 -> 0
B40: 35 | D40: =Dashboard!AK8 -> 1
B41: 36 | D41: =Dashboard!AL8 -> 0
...

Sheet SEC C & D
A1: SECTIoN C (fill with 1 or 0 only) | H1: SUMMARY
C2: Option A | D2: Option B
C3: E | D3: I | G3: =C20 -> 10 | H3: E | I3: =C20 -> 10
B4: 1 | C4: =IF(Dashboard!CU8=1,1,0) -> 1 | D4: =IF(Dashboard!CU8=0,1,0) -> 0 | G4: =D20 -> 21 | H4: I | I4: =D20 -> 21
B5: 2 | C5: =IF(Dashboard!CV8=1,1,0) -> 0 | D5: =IF(Dashboard!CV8=0,1,0) -> 1
B6: 3 | C6: =IF(Dashboard!CW8=1,1,0) -> 0 | D6: =IF(Dashboard!CW8=0,1,0) -> 1
B7: 4 | C7: =IF(Dashboard!CX8=1,1,0) -> 1 | D7: =IF(Dashboard!CX8=0,1,0) -> 0 | G7: =C40 -> 25 | H7: S | I7: =C40 -> 25
B8: 5 | C8: =IF(Dashboard!CY8=1,1,0) -> 1 | D8: =IF(Dashboard!CY8=0,1,0) -> 0 | G8: =D40 -> 8 | H8: N | I8: =D40 -> 8
B9: 6 | C9: =IF(Dashboard!CZ8=1,1,0) -> 1 | D9: =IF(Dashboard!CZ8=0,1,0) -> 0
B10: 7 | C10: =IF(Dashboard!DA8=1,1,0) -> 0 | D10: =IF(Dashboard!DA8=0,1,0) -> 1
B11: 8 | C11: =IF(Dashboard!DB8=1,1,0) -> 0 | D11: =IF(Dashboard!DB8=0,1,0) -> 1 | G11: =C62 -> 16 | H11: T | I11: =C62 -> 16
B12: 9 | C12: =IF(Dashboard!DC8=1,1,0) -> 0 | D12: =IF(Dashboard!DC8=0,1,0) -> 1 | G12: =D62 -> 19 | H12: F | I12: =D62 -> 19
B13: 10 | C13: =IF(Dashboard!DD8=1,1,0) -> 0 | D13: =IF(Dashboard!DD8=0,1,0) -> 1
B14: 11 | C14: =IF(Dashboard!DE8=1,1,0) -> 0 | D14: =IF(Dashboard!DE8=0,1,0) -> 1
B15: 12 | C15: =IF(Dashboard!DF8=1,1,0) -> 0 | D15: =IF(Dashboard!DF8=0,1,0) -> 1 | G15: =C82 -> 24 | H15: J | I15: =C82 -> 24
B16: 13 | C16: =IF(Dashboard!DG8=1,1,0) -> 0 | D16: =IF(Dashboard!DG8=0,1,0) -> 1 | G16: =D82 -> 9 | H16: P | I16: =D82 -> 9
B17: 14 | C17: =IF(Dashboard!DH8=1,1,0) -> 0 | D17: =IF(Dashboard!DH8=0,1,0) -> 1
B18: 15 | C18: =IF(Dashboard!DI8=1,1,0) -> 0 | D18: =IF(Dashboard!DI8=0,1,0) -> 1
C19: =C102+C111 -> 6 | D19: =D102+D111 -> 10
C20: =SUM(C4:C19) -> 10 | D20: =SUM(D4:D19) -> 21
C21: S | D21: N | H21: =MAX(G3:G4) -> 21 | I21: =VLOOKUP(H21,$G$3:$H$4,2,FALSE) -> I
B22: 16 | C22: =IF(Dashboard!DJ8=1,1,0) -> 0 | D22: =IF(Dashboard!DJ8=0,1,0) -> 1 | H22: =MAX(G7:G8) -> 25 | I22: =VLOOKUP(H22,$G$7:$H$8,2,FALSE) -> S
B23: 17 | C23: =IF(Dashboard!DK8=1,1,0) -> 1 | D23: =IF(Dashboard!DK8=0,1,0) -> 0 | H23: =MAX(G11:G12) -> 19 | I23: =VLOOKUP(H23,$G$11:$H$12,2,FALSE) -> F
B24: 18 | C24: =IF(Dashboard!DL8=1,1,0) -> 1 | D24: =IF(Dashboard!DL8=0,1,0) -> 0 | H24: =MAX(G15:G16) -> 24 | I24: =VLOOKUP(H24,$G$15:$H$16,2,FALSE) -> J
B25: 19 | C25: =IF(Dashboard!DM8=1,1,0) -> 0 | D25: =IF(Dashboard!DM8=0,1,0) -> 1
B26: 20 | C26: =IF(Dashboard!DN8=1,1,0) -> 1 | D26: =IF(Dashboard!DN8=0,1,0) -> 0 | I26: =CONCATENATE(I21,I22,I23,I24) -> ISFJ
B27: 21 | C27: =IF(Dashboard!DO8=1,1,0) -> 1 | D27: =IF(Dashboard!DO8=0,1,0) -> 0
B28: 22 | C28: =IF(Dashboard!DP8=1,1,0) -> 1 | D28: =IF(Dashboard!DP8=0,1,0) -> 0
B29: 23 | C29: =IF(Dashboard!DQ8=1,1,0) -> 0 | D29: =IF(Dashboard!DQ8=0,1,0) -> 1
B30: 24 | C30: =IF(Dashboard!DR8=1,1,0) -> 0 | D30: =IF(Dashboard!DR8=0,1,0) -> 1
B31: 25 | C31: =IF(Dashboard!DS8=1,1,0) -> 1 | D31: =IF(Dashboard!DS8=0,1,0) -> 0
B32: 26 | C32: =IF(Dashboard!DT8=1,1,0) -> 1 | D32: =IF(Dashboard!DT8=0,1,0) -> 0
B33: 27 | C33: =IF(Dashboard!DU8=1,1,0) -> 1 | D33: =IF(Dashboard!DU8=0,1,0) -> 0
B34: 28 | C34: =IF(Dashboard!DV8=1,1,0) -> 1 | D34: =IF(Dashboard!DV8=0,1,0) -> 0
B35: 29 | C35: =IF(Dashboard!DW8=1,1,0) -> 1 | D35: =IF(Dashboard!DW8=0,1,0) -> 0
B36: 30 | C36: =IF(Dashboard!DX8=1,1,0) -> 0 | D36: =IF(Dashboard!DX8=0,1,0) -> 1
B37: 31 | C37: =IF(Dashboard!DY8=1,1,0) -> 1 | D37: =IF(Dashboard!DY8=0,1,0) -> 0
B38: 32 | C38: =IF(Dashboard!DZ8=1,1,0) -> 1 | D38: =IF(Dashboard!DZ8=0,1,0) -> 0
C39: =F102+F111 -> 13 | D39: =G102+G111 -> 3
C40: =SUM(C22:C39) -> 25 | D40: =SUM(D22:D39) -> 8
...

Sheet SECE
B3: Count
B4: =Dashboard!HG8+Dashboard!HH8+Dashboard!JF8 -> 1 | C4: A | D4: Natural Resource Management
B5: =Dashboard!HI8+Dashboard!HJ8+Dashboard!JG8 -> 6 | C5: C | D5: Architecture and Construction
B6: =Dashboard!HK8+Dashboard!HL8+Dashboard!JH8 -> 3 | C6: V | D6: Arts , A/V & Communication
B7: 7 | C7: B | D7: Business, Management and Administration
B8: =Dashboard!HO8+Dashboard!HP8+Dashboard!JJ8 -> 4 | C8: E | D8: Education and Training
B9: =Dashboard!HQ8+Dashboard!HR8+Dashboard!JK8 -> 5 | C9: F | D9: Finance
B10: =Dashboard!HS8+Dashboard!HT8+Dashboard!JL8 -> 5 | C10: G | D10: Government and Public Administration
B11: =Dashboard!HU8+Dashboard!HV8+Dashboard!JM8 -> 5 | C11: H | D11: Health Science
B12: =Dashboard!HW8+Dashboard!HX8+Dashboard!JN8 -> 5 | C12: T | D12: Hospitality and Tourism
B13: =Dashboard!HY8+Dashboard!HZ8+Dashboard!JO8 -> 4 | C13: S | D13: Human Services
B14: 1 | C14: I | D14: Information Technology
B15: =Dashboard!IC8+Dashboard!ID8+Dashboard!JQ8 -> 3 | C15: P | D15: Public Safety and Security
B16: 8 | C16: M | D16: Manfacturing
B17: =Dashboard!IG8+Dashboard!IH8+Dashboard!JS8 -> 4 | C17: N | D17: Marketing , Sales and Service
B18: 3 | C18: Y | D18: Science, Technology, Engineering & Maths
B19: =Dashboard!IK8+Dashboard!IL8+Dashboard!JU8 -> 5 | C19: D | D19: Logistics and Distribution Management
B22: =MAX(B4:B19) -> 8
B23: =VLOOKUP(B22, B4:$C$19,2,FALSE) -> M

Sheet Report
A4: ASSESSMENT REPORT
A6: =C6&B6 -> Grade: A Level | B6: Grade: A Level
A7: School: Nixor College | B7: Date : July 2022
A9: VOCATION FINDER
A10: =VLOOKUP('SEC A & B '!$F$130,'Ans-SecA'!B5:C10,2,FALSE) -> Dominant Type: Conventional A person with a "Conventional Personality" tends to be careful, conforming, conservative, conscientious, self-controlled, and structured. Examples of conventional abilities include ordering activities and paying attention to details.
A13: PERSONALITY ANALYZER
A14: =VLOOKUP('SEC C & D'!$I$26,'Ans-SecB'!$A$2:$B$17,2,FALSE) -> Dominant Type: ISFJ ISFJs are also known as “NURTURERS”. ISFJs tend to be highly observant, stable, and practical. They have excellent memory for details and enjoy creating structure & order. Important characteristic: Ability to create structure and order.
A17: CAREER FUNNEL
A18: =VLOOKUP(SECE!B23,'Ans-SecC'!A2:B17,2,FALSE) -> Dominant Type: M - Manufacturing The manufacturing career cluster is divided into four pathways. Pathways are grouped by the knowledge and skills required of occupations in these career fields. Learners need a solid background in math, science and technical skills. The four pathways are (i) Precision Metal Production, (ii) Precision Technology Processes, (iii) Electromechanical Installation and Maintenance, and (iv) Production Design, Operations and Maintenance.
A51: C | B51: ='SEC A & B '!B135 -> 10
A52: E | B52: ='SEC A & B '!B134 -> 6
A53: S | B53: ='SEC A & B '!B133 -> 8
A54: A | B54: ='SEC A & B '!B132 -> 3
A55: I | B55: ='SEC A & B '!B131 -> 6
A56: R | B56: ='SEC A & B '!B130 -> 9

Sheet Ans-SecA
B5: R | C5: Dominant Type: Realistic A person with a "Realistic Personality" tends to be frank, practical, focused, mechanical, determined, and rugged. Examples of realistic abilities include manipulating tools, doing mechanical or manual tasks, and doing athletic activities.
B6: A | C6: Dominant Type: Artistic A person with an "Artistic Personality" tends to be complicated, original, impulsive, independent, expressive, and creative. Examples of artistic abilities include using imagination and feelings in creative expression
B7: E | C7: Dominant Type: Enterprising A person with an "Enterprising Personality" tends to be persuasive, energetic, sociable, adventurous, ambitious, and risk-taking. Examples of enterprising abilities include leading, managing, and organizing.
B8: I | C8: Dominant Type: Investigative A person with an "Investigative Personality" tends to be analytical, intellectual, reserved, independent, and scholarly. Examples of investigative abilities include working with abstract ideas and intellectual problems.
B9: S | C9: Dominant Type: Social A person with a "Social Personality" tends to be helping, informing, teaching, inspiring, counseling, and serving. Examples of social abilities include interacting with people and concerned with the welfare of people.
B10: C | C10: Dominant Type: Conventional A person with a "Conventional Personality" tends to be careful, conforming, conservative, conscientious, self-controlled, and structured. Examples of conventional abilities include ordering activities and paying attention to details.

Sheet Ans-SecB
A2: ISTJ | B2: Dominant Type: ISTJ ISTJs are also known as “DUTY FULFILLERS”. ISTJs tend to respect facts, appreciate structured / orderly environments, work long and hard to fulfill duties & are extremely observant. They dislike changes and doing things which don’t make sense to them. Important characteristic: Perseverance.
A3: ESTJ | B3: Dominant Type: ESTJ ESTJs are also known as “THE GUARDIANS”. ESTJs tend to be athletic and wholesome. They have clear set of standards, have no patience with incompetence, enjoy order and structure, and are driven to fulfill their duties. Important characteristic: Flexibility.
A4: ISFJ | B4: Dominant Type: ISFJ ISFJs are also known as “NURTURERS”. ISFJs tend to be highly observant, stable, and practical. They have excellent memory for details and enjoy creating structure & order. Important characteristic: Ability to create structure and order.
A5: ESFJ | B5: Dominant Type: ESFJ ESFJs are also known as “THE CAREGIVERS”. ESFJs tend to be organized, warm hearted and sympathetic. They enjoy variety and interacting with people. Important characteristic: Ability to create structure and order.
A6: ISTP | B6: Dominant Type: ISTP ISTPs are also known as “THE MECHANICS”. ISTPs tend to be interested in how and why things work. They have an excellent ability to apply logic and reason to their immense store of facts to solve problems or discover how things work. Important characteristic: Ability to concentrate and work through problems.
A7: ESTP | B7: Dominant Type: ESTP ESTPs are also known as “THE DOERS”. ESTPs tend to be action-oriented, fast paced and energetic. They live in the present moment, like to initiate things, and are fun to be around. Important characteristic: Ability to observe and react quickly / effectively to an immediate need.
A8: ESFP | B8: Dominant Type: ESFP ESFPs are also known as “PERFORMERS”. ESFPs tend to be stimulated and excited by new experiences. They are independent, spontaneous and are warmly interested in people. They dislike structure and routine. Important characteristic: People’s skills.
A9: ISFP | B9: Dominant Type: ISFP ISFPs are also known as “THE ARTISTS”. ISFPs tend to be individualistic, quiet and reserved. They enjoy a slower pace and like to take time to savor the present moment. They dislike routine tasks and dealing with theory or abstract thoughts (unless they see a practical application). Important characteristic: ISFPs need a great deal of space and freedom
A10: ENTJ | B10: Dominant Type: ENTJ ENTJs are also known as “THE EXECUTIVES”. ENTJs tend to be future oriented, self confident and decisive. They dislike routine and are impatient with inefficiency and incompetence. Important Characteristic: Ability to clearly identify problems and innovative solutions for the short and long-term well-being of an organization.
A11: INTJ | B11: Dominant Type: INTJ INTJs are also known as “THE SCIENTISTS”. INTJs tend to be future-oriented, calm, collected, and analytical. They prefer to work alone and are supreme strategists. They are driven to create order and structure from theoretical abstractions. Important characteristic: Ability to grasp complex theories and applying them to problems to come up with long-term strategies.
A12: ENTP | B12: Dominant Type: ENTP ENTPs are also known as “THE VISIONARIES”. ENTPs tend to be project-oriented, creative, flexible, diverse, and logical / rational thinkers. They dislike routine and detailed tasks. Important characteristic: Creativity
A13: INTP | B13: Dominant Type: INTP INTPs are also known as “THE THINKERS”. INTPs tend to be independent, original, creative, and future oriented. They love theory and abstract ideas and work best alone. Important Characteristic: Ability to quickly grasp complex abstract thoughts.
... A17: INFP | B17: Dominant Type: INFP INFPs are also known as “THE IDEALISTS”. INFPs tend to be future & growth oriented, creative, inspirational, flexible, laid-back, and individualistic. They prefer to work alone and dislike dealing with details and routine work. Important characteristic: INFPs are growth oriented.

Sheet Ans-SecC
A2: A | B2: Dominant Type: A - Natural Resource The “Natural Resource Management” cluster is divided into five pathways. Pathways are grouped by the knowledge and skills required of occupations in these career fields. Learners need a solid background in math, science, communication, and technical skills. The five pathways are (i) Agriculture Management, Production, and Operations, (ii) Horticulture, Landscaping, and Groundskeeping, (iii) Agriculture Sciences, Processes & Support Services, (iv) Mining and Operations, and (v) Conservation & Natural Resources
A3: C | B3: Dominant Type: C - Construction / Architecture The “Construction and Architecture” cluster is divided into three pathways. Pathways are grouped by the knowledge and skills required of occupations in these career fields. Learners need a solid background in math, science and technical skills. The three pathways are (i) Preconstruction and Design, (ii) Construction, and (iii) Maintenance & Operations.
A4: V | B4: Dominant Type: V - Arts / Communications The “Arts, A/V Technology and Communication” cluster is divided into six pathways. Pathways are grouped by the knowledge and skills required of occupations in these career fields. Learners need a strong background in computer and electronic based technology and a solid foundation in math, science and oral/written communication. The six pathways are (i) Visual Arts, (ii) Performing Arts, (iii) Audio/Video Technology, (iv) Journalism & Broadcasting, (v) Telecommunications & Technology, and (vi) Printing Technology.
A5: B | B5: Dominant Type: B - Management / Admin The “Business Management and Administration” cluster is divided into six pathways. Pathways are grouped by the knowledge and skills required of occupations in these career fields. Learners need a solid background in math, science and technical skills. The six pathways are (i) Financial Management and Accounting, (ii) Human Resources, (iii) Administrative and Information Support, (iv) Business Analysis, (v) Management, and (vi) Marketing and Communications
A6: E | B6: Dominant Type: E - Education / Training The “Education and Training” cluster is divided into four pathways. Pathways are grouped by the knowledge and skills required of occupations in these career fields. Learners need a solid background in academic, technical and presentation/facilitation skills. The four pathways are (i) Teaching and Training, (ii) Professional Support Services, (iii) Child Care and Teacher Aides, and (iv) Education Administration and Administrative Support.
A7: G | B7: Dominant Type: G - Govt. / Public Admin The “Government and Public Administration” cluster is divided into six pathways. Pathways are grouped by the knowledge and skills required of occupations in these career fields. Learners need a solid background in social studies, political science, and history. The six pathways are (i) Planning, (ii) Revenue & Taxation, (iii) Governance, (iv) Regulation, (v) National Security, and (vi) Foreign Service
A8: F | B8: Dominant Type: F - Finance The “Finance” cluster is divided into four pathways. Pathways are grouped by the knowledge and skills required of occupations in these career fields. Learners need a solid background in math and technical skills. The four pathways are (i) Banking and Related Services, (ii) Insurance Services, (iii) Business Financial Management, and (iv) Financial and Investment Planning.
A9: Y | B9: Dominant Type: Y - Science / Technology / Maths / Engineering The “Science, Technology, Engineering and Mathematics” cluster is divided into two pathways. Pathways are grouped by the knowledge and skills required of occupations in these career fields. Learners need a solid background in math, science, and technical skills. The two pathways are (i) Science & Mathematics, and (ii) Engineering & Technology.
A10: H | B10: Dominant Type: H - Health Science The “Health Sciences” cluster is divided into five pathways. Pathways are grouped by the knowledge and skills required of occupations in these career fields. Learners need a solid background in math, science, communications and technical skills. The five pathways are (i) Therapeutic Services, (ii) Diagnostic Services, (iii) Information and Communication Services, (iv)Support Services, & (v) Biotechnology and Pharmaceutical Services.
A11: T | B11: Dominant Type: T - Hospitality / Tourism The “Hospitality and Tourism” cluster is divided into four pathways. Pathways are grouped by the knowledge and skills required of occupations in these career fields. Learners need a solid background in math, science and technical skills. The four pathways are (i) Lodging and Housekeeping Services, (ii) Food Production and Services, (iii) Recreation, Gaming & Sports, and (iv) Travel and Tourism Services.
A12: S | B12: Dominant Type: S - Human Services The “Human Services” cluster is divided into five pathways. Pathways are grouped by the knowledge and skills required of occupations in these career fields. Learners need a solid background in communication, science and technical skills. The five pathways are (i) Early childhood development and services, (ii) Counseling and mental health services, (iii) Family and community services, (iv) Personal care services, and (v) Consumer Services.
A13: I | B13: Dominant Type: I - Information Technology The “Information Technology” cluster is divided into four pathways. Pathways are grouped by the knowledge and skills required of occupations in these career fields. Learners need a solid background in math and science. The four pathways are (i) Information Support and Services, (ii) Programming and Software Development (iii) Network Systems, and (iv) Interactive Media.
... A17: D | B17: Dominant Type: D - Logistics and Distribution The “Logistics and Distribution Management ” cluster is divided into seven pathways. Pathways are grouped by the knowledge and skills required of occupations in these career fields. Learners need a solid background in communications, math, science and technology. The seven pathways are (i) Transportation operations, (ii) Logistics planning and management services, (iii) Warehousing and distribution center operations, (iv) Sales and Service, (v) Facility and mobile equipment maintenance, (vi) Risk Management and Health and Safety Management, and (vii) Transportation Systems / Insfrastructure Planning, and Regulations.

Sheet Answer Sheet
A2: ANSWER SHEET
A4: Name: | B4: ________________________ | E4: Grade: | F4: ________________________
A5: School: | B5: ________________________ | E5: Date: | F5: ________________________
A7: Section A | D7: Section B | G7: Section C
A8: S. No | B8: Answer | D8: S. No | E8: Answer | G8: Box No. | H8: Numbers checked
A9: 1 | D9: 1 | G9: 1
A10: 2 | D10: 2 | G10: 2
A11: 3 | D11: 3 | G11: 3
A12: 4 | D12: 4 | G12: 4
A13: 5 | D13: 5 | G13: 5
A14: 6 | D14: 6 | G14: 6
A15: 7 | D15: 7 | G15: 7
A16: 8 | D16: 8 | G16: 8
A17: 9 | D17: 9 | G17: 9
A18: 10 | D18: 10 | G18: 10
A19: 11 | D19: 11 | G19: 11
A20: 12 | D20: 12 | G20: 12
... A24: 16 | D24: 16 | G24: 16
A25: 17 | D25: 17
A26: 18
A27: 19
A28: 20
A29: 21
A30: 22
A31: 23
A32: 24
